Workbook

Sheet Leyenda
A1: Eventos del PDF "SimuladorSociales - Juego de Rol"
A3: Qué hay acá
B4: Los 67 eventos del PDF, transcritos completos: enunciado, respuestas, efectos, probabilidades y variaciones de stats. Una fila por EFECTO, que es la unidad más chica.
B5: Los minijuegos NO están en este archivo: quedan como están en el juego.
A7: De dónde sale cada evento
B8: La columna origen_pdf conserva la sección y el número del PDF (Generales 12, Guita 4, Historia 3) para poder volver al documento. Es solo trazabilidad.
B9: Por pedido tuyo, TODOS entran al juego como eventos generales: no se clasifican por guita / conocimiento / fama / política.
B10: La historia "El Cambio Social" del final del PDF está tomada como cinco eventos sueltos (Historia 1 a 5), sin encadenar.
A12: Cómo leer las columnas
A13: id | B13: EV01 a EV67. Agrupa las filas de un mismo evento.
A14: nivel | B14: Solo si el PDF lo aclara (Ingresante / Intermedio / Avanzado / Mitad de carrera). La mayoría viene vacío.
A15: n_resp | B15: Número de respuesta dentro del evento.
A16: n_efecto | B16: Número de efecto dentro de esa respuesta. Si hay más de uno, se sortea por probabilidad.
A17: probabilidad | B17: Del PDF. Los efectos de una misma respuesta suman 100%.
A18: guita ... politica | B18: Valor sugerido para cada stat. Vacío = el PDF no indica nada.
A19: notacion_pdf | B19: La notación literal del documento (+fama, --guita). Es la fuente; los números de al lado son una traducción.
A20: especial | B20: Marcado en amarillo. Cosas que no son un simple cambio de stats: minijuego, salida de carrera, termina partida, escalada de violencia, perdés un cuatrimestre, efectos condicionales.
A21: notas | B21: Aclaraciones sobre ambigüedades del PDF.
B28: Cuando el PDF da un número explícito (por ejemplo "-20 conocimiento" o "+3 de conocimiento") se respetó ese número y se aclaró en notas.
B29: Estos valores son una PROPUESTA: cambialos en las columnas de stats y el Resumen se actualiza solo.
A31: Qué falta decidir
B32: Hay eventos donde el PDF describe el resultado pero no asigna ninguna variación de stats. Quedaron con las cuatro columnas vacías, listos para que les pongas valor.
B33: Filtrá la hoja Eventos por guita/conocimiento/fama/politica vacíos para encontrarlos.
A35: La escala de puntos (actualizada)
B36: El PDF marca intensidad con signos, no con números. La escala vieja del juego era + = 5, ++ = 9, +++ = 14, pensada para partidas largas. Con solo 6 eventos por partida cada carta tiene que pesar mucho más, así que se multiplicó por 2,5:
A37: + / - | B37: 12 / -12
A38: ++ / -- | B38: 22 / -22
A39: +++ / --- | B39: 35 / -35
B40: Los números explícitos del PDF (+3, +5, -10, -20) se escalaron igual: quedan en 8, 12, -25 y -50.
A42: Balance de los cuatro stats
B43: Neto de cada uno sumando los 208 efectos: guita +30, conocimiento +40, fama +24, política +46. Proporcionalmente es el mismo equilibrio que antes de escalar; lo que importa es que ninguno quede muy por encima del resto.
B44: Los 109 valores del PDF venían torcidos: guita cerraba en -43 y política en +72 (en la escala vieja). Los 99 completados se usaron para emparejarlos.
A46: Arranque y bandas: hay que cambiarlos al cargar
B47: Simulando 30.000 partidas de 6 eventos con estos valores:
A48: arranque | B48: Los stats pasan a arrancar entre 40 y 60 (hoy es 24-36). Con saltos de 12 a 35 hace falta ese margen: si no, los stats se clavan en 0 y las últimas decisiones dejan de tener efecto.
A49: resultado | B49: Los stats terminan entre 10 y 91 (p5 y p95), con mediana 51. Solo el 2,5% queda clavado en 0 y otro 2,5% en 100.
A50: bandas | B50: Los cortes actuales (ALTA 40, BAJA 28) quedan obsoletos: con este arranque todos empezarían ya en ALTA. Los que mejor reparten son ALTA >= 60 y BAJA <= 36, o sea MEDIA de 37 a 59.
B51: Con esos cortes: 1 stat en alta 37,5% de las partidas, dupla 30,9%, trío 12,2%, ninguna en alta 17,7%, las cuatro en alta 1,6%. Muy parecido a lo que da el juego hoy.
B52: Nada de esto está en el Excel: son tres valores de db/contenido.js y db/seed.js que hay que tocar cuando se cargue el contenido.

Sheet Eventos
A1: id | B1: origen_pdf | C1: nivel | D1: titulo | E1: enunciado | F1: n_resp | G1: respuesta | H1: n_efecto | I1: probabilidad | J1: resultado | K1: guita | L1: conocimiento | M1: fama | N1: politica | O1: notacion_pdf | P1: origen_valores | Q1: especial | R1: notas
A2: EV01 | B2: Generales 1 | D2: David Lynch en la plaza seca | E2: Te quedás ranchando en la plaza seca y ves a una mina linda que nunca antes habías visto en tu vida. Un facuamigo te la presenta y resulta que los dos son fanáticos de David Lynch. Te enamorás profundamente. Al otro día tenés un coloquio en grupo importantísimo. Si no ponés de tu parte todo tu grupo se verá afectado. | F2: 1 | G2: Te quedás hasta las mil y una hablando con esta piba. Dios, Patria y Familia. En una de esas te terminás casando y se te resuelven la mitad de los problemas. Los compas sabrán entender. | H2: 1 | I2: 1 | J2: Los compas no supieron entender. | L2: -12 | M2: -12 | O2: -fama -conocimiento | P2: PDF
A3: EV01 | B3: Generales 1 | D3: David Lynch en la plaza seca | E3: Te quedás ranchando en la plaza seca y ves a una mina linda que nunca antes habías visto en tu vida. Un facuamigo te la presenta y resulta que los dos son fanáticos de David Lynch. Te enamorás profundamente. Al otro día tenés un coloquio en grupo importantísimo. Si no ponés de tu parte todo tu grupo se verá afectado. | F3: 2 | G3: Si es la indicada va a saber entender. Existe la posibilidad de que se corte el hechizo y no la veas más en tu vida. Intercambian instagrams. | H3: 1 | I3: 0.3 | J3: Resulta que era una militante de alternativa académica. Los abuelos tienen terrenos en la Pampa Húmeda. | K3: 12 | O3: +guita | P3: PDF | Q3: condicional | R3: En el PDF: si el jugador tiene guita pega onda (+guita); si no tiene un mango se le va la chance.
A4: EV01 | B4: Generales 1 | D4: David Lynch en la plaza seca | E4: Te quedás ranchando en la plaza seca y ves a una mina linda que nunca antes habías visto en tu vida. Un facuamigo te la presenta y resulta que los dos son fanáticos de David Lynch. Te enamorás profundamente. Al otro día tenés un coloquio en grupo importantísimo. Si no ponés de tu parte todo tu grupo se verá afectado. | F4: 2 | G4: Si es la indicada va a saber entender. Existe la posibilidad de que se corte el hechizo y no la veas más en tu vida. Intercambian instagrams. | H4: 2 | I4: 0.7 | J4: Se cortó el hechizo y no la viste nunca más. | N4: -12 | O4: -politica | P4: PDF
A5: EV02 | B5: Generales 2 | D5: El último bondi | E5: Te quedaste ranchando hasta cualquier hora con los pibes y vivís en Temperley. Llegás a la avenida y ves el último bondi que se te va. | F5: 1 | G5: Corrés el bondi. | H5: 1 | I5: 0.5 | J5: Llegás pero se te abrió la mochila y se te cayó todo. En el camino quedaron tus apuntes sobre Weber, Hobbes y Ofelia Fernández. Habrá que comenzar de nuevo. | K5: -12 | L5: -12 | O5: -conocimiento -guita | P5: PDF
A6: EV02 | B6: Generales 2 | D6: El último bondi | E6: Te quedaste ranchando hasta cualquier hora con los pibes y vivís en Temperley. Llegás a la avenida y ves el último bondi que se te va. | F6: 1 | G6: Corrés el bondi. | H6: 2 | I6: 0.5 | J6: Corrés el bondi pero te tropezás y caés. Te ayuda una chica que iba a subir pero se quedó preocupada por tu caída. Resulta que vive en la misma zona que vos y cursa T. S. Es el alma más noble que conociste en tu vida. Se van a tomar algo hasta cualquier hora. Quiere tus defectos más que tus virtudes (que no sobran). Contás la anécdota y tus amigos te cambian el apodo por Lilita Corrió. Tenés novia. | K6: -12 | L6: 12 | M6: 12 | O6: -guita +fama +conocimiento | P6: PDF
A7: EV02 | B7: Generales 2 | D7: El último bondi | E7: Te quedaste ranchando hasta cualquier hora con los pibes y vivís en Temperley. Llegás a la avenida y ves el último bondi que se te va. | F7: 2 | G7: No te apurás. Ya llegará otro. | H7: 1 | I7: 1 | J7: Estuviste tres horas esperando el bondi chupando frío. Te quisieron robar y las chicas que laburan en Consti saltaron por vos. Les contaste lo que estudiabas. Arrancás una movida contra la represión de la policía en el barrio contra las trabajadoras sexuales. | K7: -12 | M7: 12 | N7: 12 | O7: -guita +fama +politica | P7: PDF
A8: EV03 | B8: Generales 3 | D8: El que pide plata | E8: Entra una persona a pedir plata a la facultad. Dice que lo persigue Máximo Kirchner, que necesita plata para irse del país porque tiene información que puede llevar al arresto de la Dra. Cristina Fernández de Kirchner. | F8: 1 | G8: Le das plata. | H8: 1 | I8: 1 | J8: El tipo te agradece y dice que quiere mostrarte algo. Te lleva al baño. Tenés miedo pero lo seguís. "Acercate", susurra. Mete la mano por debajo del cuello y se saca una máscara: ¡es Nisman! | K8: -12 | N8: 12 | O8: -guita +politica | P8: PDF
A9: EV03 | B9: Generales 3 | D9: El que pide plata | E9: Entra una persona a pedir plata a la facultad. Dice que lo persigue Máximo Kirchner, que necesita plata para irse del país porque tiene información que puede llevar al arresto de la Dra. Cristina Fernández de Kirchner. | F9: 2 | G9: No le creés. | H9: 1 | I9: 1 | J9: El tipo se aleja sin problema. Antes de doblar la esquina un francotirador lo fulmina con un tiro en la frente. No llegás a ver de dónde dispararon pero hay humo en una ventana de la esquina de San José. | K9: 12 | M9: -12 | O9: +guita -fama | P9: PDF
A10: EV04 | B10: Generales 4 | D10: ¿Dónde vas a estudiar? | E10: Llegás temprano a la facultad por primera vez en tu vida. ¿A dónde vas a estudiar? | F10: 1 | G10: A la biblioteca. Obviamente. | H10: 1 | I10: 1 | J10: De tanto silencio te quedaste dormido. Llegaste tarde a la clase pero la siesta te hizo bien. Lo poco que estuviste participaste un montón. | L10: 12 | P10: propuesto
A11: EV04 | B11: Generales 4 | D11: ¿Dónde vas a estudiar? | E11: Llegás temprano a la facultad por primera vez en tu vida. ¿A dónde vas a estudiar? | F11: 2 | G11: Te encerrás en un aula vacía. | H11: 1 | I11: 1 | J11: A los quince minutos entró un grupo para una clase. Como te dio vergüenza te quedaste. Terminás aprendiendo mucho sobre Martín Lutero. | L11: 12 | P11: propuesto
A12: EV04 | B12: Generales 4 | D12: ¿Dónde vas a estudiar? | E12: Llegás temprano a la facultad por primera vez en tu vida. ¿A dónde vas a estudiar? | F12: 3 | G12: Agarrás una mesa en el foyer. | H12: 1 | I12: 1 | J12: Mala luz y letra minúscula. Entraste a cursar sin ver un pito. Encima no aprendiste un carajo. | L12: -12 | P12: propuesto
A13: EV05 | B13: Generales 5 | D13: Trabajo de investigación | E13: Tenés que hacer un trabajo de investigación en grupo. | F13: 1 | G13: Elegís el tema difícil. No solo se trata de aprobar la materia. Vas a aprender un montón. | H13: 1 | I13: 1 | J13: Le dedicás una banda de tiempo, queda bien y le gustó a la cátedra. | L13: 22 | P13: propuesto
A14: EV05 | B14: Generales 5 | D14: Trabajo de investigación | E14: Tenés que hacer un trabajo de investigación en grupo. | F14: 2 | G14: Elegís un tema papita que mucho no te interesa. Ese trabajo se va a redactar solo. | H14: 1 | I14: 1 | J14: Lo hiciste el día anterior. Te sacaste de encima la materia y fuiste a final. En el medio te hiciste nuevos facuamigos igual de vagos que vos. | L14: -12 | M14: 12 | P14: propuesto
A15: EV06 | B15: Generales 6 | D15: Clase muy embolante | E15: Clase muy embolante. | F15: 1 | G15: Dejás grabando el audio con el celular y te dormís. Si el profesor se da cuenta te podés ganar el odio para toda la cursada. | H15: 1 | I15: 0.5 | J15: El profesor se da cuenta. Te hace la vida imposible hasta el final. Recursás el cuatri siguiente pero en la otra cátedra. | L15: -22 | M15: -12 | P15: propuesto
A16: EV06 | B16: Generales 6 | D16: Clase muy embolante | E16: Clase muy embolante. | F16: 1 | G16: Dejás grabando el audio con el celular y te dormís. Si el profesor se da cuenta te podés ganar el odio para toda la cursada. | H16: 2 | I16: 0.5 | J16: El profesor se da cuenta pero le chupa un huevo. Es más, te ofrece un drive con los audios de todas las clases. Tu Samsung Pocket lo agradece. Con ese material aprendés un montón. | L16: 22 | P16: propuesto
A17: EV06 | B17: Generales 6 | D17: Clase muy embolante | E17: Clase muy embolante. | F17: 2 | G17: Te vas a comprar un café para remontarla. Es solo un mal momento. | H17: 1 | I17: 1 | J17: El exquisito café de las máquinas del CeXSo te hace efecto. La rompés. Y tan solo por 2000 pesos argensimios. | K17: -12 | L17: 12 | P17: propuesto
A18: EV06 | B18: Generales 6 | D18: Clase muy embolante | E18: Clase muy embolante. | F18: 3 | G18: Salís y hablás un rato con tu facuamigo que está haciendo tiempo. | H18: 1 | I18: 1 | J18: Te cuenta que va a ser papá y que los pañales están muy caros. Volvés y le metés con todo a la clase. En un futuro esos pañales no se van a pagar solos. | L18: 22 | P18: propuesto
A19: EV07 | B19: Generales 7 | D19: El que no para de decir boludeces | E19: Un pibe no para de decir boludeces en clase. El profesor ya no sabe cómo hacerle entender que está diciendo gansadas. | F19: 1 | G19: Te hacés cargo y tirás un "mejor escuchar la explicación del profesor". | H19: 1 | I19: 1 | J19: Los demás te lo agradecen y el profesor también, aunque quedás medio chupamedias. El pibe no volvió a acotar nunca más en su vida. | L19: 12 | M19: -12 | P19: propuesto
A20: EV07 | B20: Generales 7 | D20: El que no para de decir boludeces | E20: Un pibe no para de decir boludeces en clase. El profesor ya no sabe cómo hacerle entender que está diciendo gansadas. | F20: 2 | G20: No decís nada. La mejor forma de aprender es equivocándose. | H20: 1 | I20: 1 | J20: A la otra clase el pibe dejó la materia. | L20: 12 | P20: propuesto
A21: EV07 | B21: Generales 7 | D21: El que no para de decir boludeces | E21: Un pibe no para de decir boludeces en clase. El profesor ya no sabe cómo hacerle entender que está diciendo gansadas. | F21: 3 | G21: Agarrás el fierro caliente y le explicás lo que está diciendo mal. | H21: 1 | I21: 1 | J21: Vos también lo decís mal. El profesor abandona la cátedra por estar rodeado de pelotudos. Ahora es influencer de tarot marxista. | L21: -12 | M21: -12 | P21: propuesto
A22: EV08 | B22: Generales 8 | D22: ¿Por qué siguen acumulando? | E22: La profesora pregunta por qué los multimillonarios siguen acumulando pese a tener mucho dinero. | F22: 1 | G22: Para comer buena carne. | H22: 1 | I22: 1 | J22: Boca, Perón y El Diego. La solución a la globalización es el nacionalismo. | L22: -12 | M22: 12 | P22: propuesto
A23: EV08 | B23: Generales 8 | D23: ¿Por qué siguen acumulando? | E23: La profesora pregunta por qué los multimillonarios siguen acumulando pese a tener mucho dinero. | F23: 2 | G23: Hay que expropiarlos a todos. Buscar un por qué te chupa un huevo. | H23: 1 | I23: 1 | J23: Se notaron tus inclinaciones marxistas. | L23: -12 | N23: 12 | P23: propuesto
A24: EV08 | B24: Generales 8 | D24: ¿Por qué siguen acumulando? | E24: La profesora pregunta por qué los multimillonarios siguen acumulando pese a tener mucho dinero. | F24: 3 | G24: Para hacer fiestas gay con enanos. | H24: 1 | I24: 1 | J24: Quisiste hacer un chiste y no salió. Los demás te miraron medio raro. | M24: -12 | P24: propuesto
A25: EV08 | B25: Generales 8 | D25: ¿Por qué siguen acumulando? | E25: La profesora pregunta por qué los multimillonarios siguen acumulando pese a tener mucho dinero. | F25: 4 | G25: Porque no saben hacer otra cosa más que seguir el fetiche del dinero. | H25: 1 | I25: 1 | J25: A la profe le cerró bastante tu respuesta y te lo hace saber. Te motivás y mejorás tu desempeño. | L25: 22 | P25: propuesto
A26: EV09 | B26: Generales 9 | D26: El fan de Charles Manson | E26: Un compañero te cuenta que está fanatizado con Charles Manson, que era un incomprendido social y que lo que hizo estaba bien. | F26: 1 | G26: Ya se va a curar. Solo es medio raro. | H26: 1 | I26: 1 | J26: Mató a un cheto medio hippie de Comunicación Social. | M26: -12 | N26: -12 | P26: propuesto | Q26: violencia
A27: EV09 | B27: Generales 9 | D27: El fan de Charles Manson | E27: Un compañero te cuenta que está fanatizado con Charles Manson, que era un incomprendido social y que lo que hizo estaba bien. | F27: 2 | G27: Lo denunciás con las autoridades de la facultad. Se puede solucionar. | H27: 1 | I27: 1 | J27: Lo echan pero ni se entera de que fuiste vos. Ya lo sabía todo el mundo. | M27: 12 | N27: 12 | P27: propuesto
A28: EV09 | B28: Generales 9 | D28: El fan de Charles Manson | E28: Un compañero te cuenta que está fanatizado con Charles Manson, que era un incomprendido social y que lo que hizo estaba bien. | F28: 3 | G28: Armás un linchamiento sorpresa para tu amigo. La historia se repite... | H28: 1 | I28: 1 | J28: Se zarpan y lo matan. Mejor que ser oprimido. | M28: -12 | N28: -22 | P28: propuesto | Q28: violencia
A29: EV10 | B29: Generales 10 | D29: Final a las cinco de la tarde | E29: Tenés un final a las cinco de la tarde, tenés el día libre y no sabés nada. | F29: 1 | G29: Das la cara y sos sincero. Zafás y te ponen ausente o te comés un uno. | H29: 1 | I29: 0.5 | J29: Zafaste: te ponen ausente. | L29: -12 | P29: propuesto
A30: EV10 | B30: Generales 10 | D30: Final a las cinco de la tarde | E30: Tenés un final a las cinco de la tarde, tenés el día libre y no sabés nada. | F30: 1 | G30: Das la cara y sos sincero. Zafás y te ponen ausente o te comés un uno. | H30: 2 | I30: 0.5 | J30: Te comiste un uno. | L30: -22 | P30: propuesto
A31: EV10 | B31: Generales 10 | D31: Final a las cinco de la tarde | E31: Tenés un final a las cinco de la tarde, tenés el día libre y no sabés nada. | F31: 2 | G31: Te mirás un video motivacional de Locomotora Olivera, te tomás un mango loco, leés un resumen de sesenta páginas que conseguiste y salís a la cancha. | H31: 1 | I31: 0.8 | J31: Te fue como el orto, pero las ganas de comerte el mundo no te las saca nadie. | L31: -12 | M31: 12 | P31: propuesto
A32: EV10 | B32: Generales 10 | D32: Final a las cinco de la tarde | E32: Tenés un final a las cinco de la tarde, tenés el día libre y no sabés nada. | F32: 2 | G32: Te mirás un video motivacional de Locomotora Olivera, te tomás un mango loco, leés un resumen de sesenta páginas que conseguiste y salís a la cancha. | H32: 2 | I32: 0.2 | J32: La cafeína llegó al cerebro y saliste de la caverna así como decía Platón. Accediste a las Ideas y a partir de ahora creés en la Matrix. Te sacaste un 10. | L32: 22 | P32: propuesto
A33: EV11 | B33: Generales 11 | D33: El after y el Pity | E33: Cursás los sábados y no te quedan más faltas (sí, toman falta). El viernes salís pensando ir pasado de rosca a cursar, pero tu amigo consigue un after. Y está el Pity. | F33: 1 | G33: Me quedo libre pero conozco al Pity. Homero tiene más valor social que toda la obra de Talcott Parsons. La foto con él se la mostrás hasta a los perros. | H33: 1 | I33: 1 | J33: Quedaste libre. La foto con el Pity la tenés de fondo de pantalla. | L33: -12 | M33: 22 | P33: propuesto
A34: EV11 | B34: Generales 11 | D34: El after y el Pity | E34: Cursás los sábados y no te quedan más faltas (sí, toman falta). El viernes salís pensando ir pasado de rosca a cursar, pero tu amigo consigue un after. Y está el Pity. | F34: 2 | G34: Voy a cursar. No me queda otra. La próxima será. | H34: 1 | I34: 1 | J34: Fuiste a cursar. El Pity siguió existiendo sin vos. | L34: 12 | M34: -12 | P34: propuesto
A35: EV12 | B35: Generales 12 | D35: La sala de radio | E35: Pasás por la sala de radio y te das cuenta de que adentro hay dos del centro de estudiantes dándose masa. Tienen un candado aparte para asegurarse el telo. | F35: 1 | G35: Los mandás al frente. Corrés el riesgo de que sea para un trabajo práctico. | H35: 1 | I35: 1 | J35: Expusiste al CeXSo y a las autoridades. Para el estudiantado quedaste como el espía del amor. | M35: 12 | O35: +fama | P35: PDF
A36: EV12 | B36: Generales 12 | D36: La sala de radio | E36: Pasás por la sala de radio y te das cuenta de que adentro hay dos del centro de estudiantes dándose masa. Tienen un candado aparte para asegurarse el telo. | F36: 2 | G36: No soy vigilante. Además hay que subir la tasa de fecundidad. | H36: 1 | I36: 1 | J36: Sale a la luz por una foto. Era un curso intensivo con aproximación realista a la educación sexual. | K36: 0 | L36: 0 | M36: 0 | N36: 0 | P36: propuesto
A37: EV13 | B37: Generales 13 | D37: ¿Era linda? | E37: Le decís a tu novia que viste a una chica en la facultad que se parece a ella. Te pregunta si era linda. | F37: 1 | G37: Le decís que la chica era linda. | H37: 1 | I37: 1 | J37: Te puteó de arriba a abajo en el Burger, se podía escuchar a nenes llorando. Digamos que te quedaste sin novia y ni siquiera pudiste disfrutar de la hamburguesa. | M37: -12 | P37: propuesto
A38: EV13 | B38: Generales 13 | D38: ¿Era linda? | E38: Le decís a tu novia que viste a una chica en la facultad que se parece a ella. Te pregunta si era linda. | F38: 2 | G38: Le decís que la chica no era linda. | H38: 1 | I38: 1 | J38: Te puteó de arriba a abajo en el Burger, se podía escuchar a nenes llorando. Digamos que te quedaste sin novia y ni siquiera pudiste disfrutar de la hamburguesa. | M38: -12 | P38: propuesto | R38: En el PDF las dos respuestas tienen exactamente el mismo efecto. Es el chiste.
A39: EV14 | B39: Generales 14 | D39: Michael Jackson en la puerta | E39: Al salir de la facultad ves que hay un tipo vestido de Michael Jackson bailando y cantando. Al acercarte te dice "hee-hee". | F39: 1 | G39: Lo cagás a piñas. | H39: 1 | I39: 0.5 | J39: Tus compañeros no te pueden sacar de encima de Michael, se tuvo que meter la policía incluso. Otra denuncia más a la lista. | K39: -12 | O39: -guita | P39: PDF | Q39: violencia
A40: EV14 | B40: Generales 14 | D40: Michael Jackson en la puerta | E40: Al salir de la facultad ves que hay un tipo vestido de Michael Jackson bailando y cantando. Al acercarte te dice "hee-hee". | F40: 1 | G40: Lo cagás a piñas. | H40: 2 | I40: 0.5 | J40: No era un tipo vestido de Michael: era el verdadero Michael Jackson, que había venido a la Argentina en secreto. En los ojos del mundo quedás como un hijo de puta, peor que Chapman. | M40: -22 | N40: -22 | O40: --fama --politica | P40: PDF | Q40: violencia
...

Sheet Resumen
A1: id | B1: origen_pdf | C1: nivel | D1: titulo | E1: respuestas | F1: efectos | G1: suma guita | H1: suma conocimiento | I1: suma fama | J1: suma politica | K1: especiales
A2: EV01 | B2: Generales 1 | D2: David Lynch en la plaza seca | E2: =COUNTIFS(Eventos!$A$2:$A$209,$A2,Eventos!$H$2:$H$209,1) -> 2 | F2: =COUNTIF(Eventos!$A$2:$A$209,$A2) -> 3 | G2: =SUMIF(Eventos!$A$2:$A$209,$A2,Eventos!$K$2:$K$209) -> 12 | H2: =SUMIF(Eventos!$A$2:$A$209,$A2,Eventos!$L$2:$L$209) -> -12 | I2: =SUMIF(Eventos!$A$2:$A$209,$A2,Eventos!$M$2:$M$209) -> -12 | J2: =SUMIF(Eventos!$A$2:$A$209,$A2,Eventos!$N$2:$N$209) -> -12 | K2: =COUNTIFS(Eventos!$A$2:$A$209,$A2,Eventos!$Q$2:$Q$209,"<>") -> 1
A3: EV02 | B3: Generales 2 | D3: El último bondi | E3: =COUNTIFS(Eventos!$A$2:$A$209,$A3,Eventos!$H$2:$H$209,1) -> 2 | F3: =COUNTIF(Eventos!$A$2:$A$209,$A3) -> 3 | G3: =SUMIF(Eventos!$A$2:$A$209,$A3,Eventos!$K$2:$K$209) -> -36 | H3: =SUMIF(Eventos!$A$2:$A$209,$A3,Eventos!$L$2:$L$209) -> 0 | I3: =SUMIF(Eventos!$A$2:$A$209,$A3,Eventos!$M$2:$M$209) -> 24 | J3: =SUMIF(Eventos!$A$2:$A$209,$A3,Eventos!$N$2:$N$209) -> 12 | K3: =COUNTIFS(Eventos!$A$2:$A$209,$A3,Eventos!$Q$2:$Q$209,"<>") -> 0
A4: EV03 | B4: Generales 3 | D4: El que pide plata | E4: =COUNTIFS(Eventos!$A$2:$A$209,$A4,Eventos!$H$2:$H$209,1) -> 2 | F4: =COUNTIF(Eventos!$A$2:$A$209,$A4) -> 2 | G4: =SUMIF(Eventos!$A$2:$A$209,$A4,Eventos!$K$2:$K$209) -> 0 | H4: =SUMIF(Eventos!$A$2:$A$209,$A4,Eventos!$L$2:$L$209) -> 0 | I4: =SUMIF(Eventos!$A$2:$A$209,$A4,Eventos!$M$2:$M$209) -> -12 | J4: =SUMIF(Eventos!$A$2:$A$209,$A4,Eventos!$N$2:$N$209) -> 12 | K4: =COUNTIFS(Eventos!$A$2:$A$209,$A4,Eventos!$Q$2:$Q$209,"<>") -> 0
A5: EV04 | B5: Generales 4 | D5: ¿Dónde vas a estudiar? | E5: =COUNTIFS(Eventos!$A$2:$A$209,$A5,Eventos!$H$2:$H$209,1) -> 3 | F5: =COUNTIF(Eventos!$A$2:$A$209,$A5) -> 3 | G5: =SUMIF(Eventos!$A$2:$A$209,$A5,Eventos!$K$2:$K$209) -> 0 | H5: =SUMIF(Eventos!$A$2:$A$209,$A5,Eventos!$L$2:$L$209) -> 12 | I5: =SUMIF(Eventos!$A$2:$A$209,$A5,Eventos!$M$2:$M$209) -> 0 | J5: =SUMIF(Eventos!$A$2:$A$209,$A5,Eventos!$N$2:$N$209) -> 0 | K5: =COUNTIFS(Eventos!$A$2:$A$209,$A5,Eventos!$Q$2:$Q$209,"<>") -> 0
A6: EV05 | B6: Generales 5 | D6: Trabajo de investigación | E6: =COUNTIFS(Eventos!$A$2:$A$209,$A6,Eventos!$H$2:$H$209,1) -> 2 | F6: =COUNTIF(Eventos!$A$2:$A$209,$A6) -> 2 | G6: =SUMIF(Eventos!$A$2:$A$209,$A6,Eventos!$K$2:$K$209) -> 0 | H6: =SUMIF(Eventos!$A$2:$A$209,$A6,Eventos!$L$2:$L$209) -> 10 | I6: =SUMIF(Eventos!$A$2:$A$209,$A6,Eventos!$M$2:$M$209) -> 12 | J6: =SUMIF(Eventos!$A$2:$A$209,$A6,Eventos!$N$2:$N$209) -> 0 | K6: =COUNTIFS(Eventos!$A$2:$A$209,$A6,Eventos!$Q$2:$Q$209,"<>") -> 0
A7: EV06 | B7: Generales 6 | D7: Clase muy embolante | E7: =COUNTIFS(Eventos!$A$2:$A$209,$A7,Eventos!$H$2:$H$209,1) -> 3 | F7: =COUNTIF(Eventos!$A$2:$A$209,$A7) -> 4 | G7: =SUMIF(Eventos!$A$2:$A$209,$A7,Eventos!$K$2:$K$209) -> -12 | H7: =SUMIF(Eventos!$A$2:$A$209,$A7,Eventos!$L$2:$L$209) -> 34 | I7: =SUMIF(Eventos!$A$2:$A$209,$A7,Eventos!$M$2:$M$209) -> -12 | J7: =SUMIF(Eventos!$A$2:$A$209,$A7,Eventos!$N$2:$N$209) -> 0 | K7: =COUNTIFS(Eventos!$A$2:$A$209,$A7,Eventos!$Q$2:$Q$209,"<>") -> 0
A8: EV07 | B8: Generales 7 | D8: El que no para de decir boludeces | E8: =COUNTIFS(Eventos!$A$2:$A$209,$A8,Eventos!$H$2:$H$209,1) -> 3 | F8: =COUNTIF(Eventos!$A$2:$A$209,$A8) -> 3 | G8: =SUMIF(Eventos!$A$2:$A$209,$A8,Eventos!$K$2:$K$209) -> 0 | H8: =SUMIF(Eventos!$A$2:$A$209,$A8,Eventos!$L$2:$L$209) -> 12 | I8: =SUMIF(Eventos!$A$2:$A$209,$A8,Eventos!$M$2:$M$209) -> -24 | J8: =SUMIF(Eventos!$A$2:$A$209,$A8,Eventos!$N$2:$N$209) -> 0 | K8: =COUNTIFS(Eventos!$A$2:$A$209,$A8,Eventos!$Q$2:$Q$209,"<>") -> 0
A9: EV08 | B9: Generales 8 | D9: ¿Por qué siguen acumulando? | E9: =COUNTIFS(Eventos!$A$2:$A$209,$A9,Eventos!$H$2:$H$209,1) -> 4 | F9: =COUNTIF(Eventos!$A$2:$A$209,$A9) -> 4 | G9: =SUMIF(Eventos!$A$2:$A$209,$A9,Eventos!$K$2:$K$209) -> 0 | H9: =SUMIF(Eventos!$A$2:$A$209,$A9,Eventos!$L$2:$L$209) -> -2 | I9: =SUMIF(Eventos!$A$2:$A$209,$A9,Eventos!$M$2:$M$209) -> 0 | J9: =SUMIF(Eventos!$A$2:$A$209,$A9,Eventos!$N$2:$N$209) -> 12 | K9: =COUNTIFS(Eventos!$A$2:$A$209,$A9,Eventos!$Q$2:$Q$209,"<>") -> 0
A10: EV09 | B10: Generales 9 | D10: El fan de Charles Manson | E10: =COUNTIFS(Eventos!$A$2:$A$209,$A10,Eventos!$H$2:$H$209,1) -> 3 | F10: =COUNTIF(Eventos!$A$2:$A$209,$A10) -> 3 | G10: =SUMIF(Eventos!$A$2:$A$209,$A10,Eventos!$K$2:$K$209) -> 0 | H10: =SUMIF(Eventos!$A$2:$A$209,$A10,Eventos!$L$2:$L$209) -> 0 | I10: =SUMIF(Eventos!$A$2:$A$209,$A10,Eventos!$M$2:$M$209) -> -12 | J10: =SUMIF(Eventos!$A$2:$A$209,$A10,Eventos!$N$2:$N$209) -> -22 | K10: =COUNTIFS(Eventos!$A$2:$A$209,$A10,Eventos!$Q$2:$Q$209,"<>") -> 2
A11: EV10 | B11: Generales 10 | D11: Final a las cinco de la tarde | E11: =COUNTIFS(Eventos!$A$2:$A$209,$A11,Eventos!$H$2:$H$209,1) -> 2 | F11: =COUNTIF(Eventos!$A$2:$A$209,$A11) -> 4 | G11: =SUMIF(Eventos!$A$2:$A$209,$A11,Eventos!$K$2:$K$209) -> 0 | H11: =SUMIF(Eventos!$A$2:$A$209,$A11,Eventos!$L$2:$L$209) -> -24 | I11: =SUMIF(Eventos!$A$2:$A$209,$A11,Eventos!$M$2:$M$209) -> 12 | J11: =SUMIF(Eventos!$A$2:$A$209,$A11,Eventos!$N$2:$N$209) -> 0 | K11: =COUNTIFS(Eventos!$A$2:$A$209,$A11,Eventos!$Q$2:$Q$209,"<>") -> 0
A12: EV11 | B12: Generales 11 | D12: El after y el Pity | E12: =COUNTIFS(Eventos!$A$2:$A$209,$A12,Eventos!$H$2:$H$209,1) -> 2 | F12: =COUNTIF(Eventos!$A$2:$A$209,$A12) -> 2 | G12: =SUMIF(Eventos!$A$2:$A$209,$A12,Eventos!$K$2:$K$209) -> 0 | H12: =SUMIF(Eventos!$A$2:$A$209,$A12,Eventos!$L$2:$L$209) -> 0 | I12: =SUMIF(Eventos!$A$2:$A$209,$A12,Eventos!$M$2:$M$209) -> 10 | J12: =SUMIF(Eventos!$A$2:$A$209,$A12,Eventos!$N$2:$N$209) -> 0 | K12: =COUNTIFS(Eventos!$A$2:$A$209,$A12,Eventos!$Q$2:$Q$209,"<>") -> 0
A13: EV12 | B13: Generales 12 | D13: La sala de radio | E13: =COUNTIFS(Eventos!$A$2:$A$209,$A13,Eventos!$H$2:$H$209,1) -> 2 | F13: =COUNTIF(Eventos!$A$2:$A$209,$A13) -> 2 | G13: =SUMIF(Eventos!$A$2:$A$209,$A13,Eventos!$K$2:$K$209) -> 0 | H13: =SUMIF(Eventos!$A$2:$A$209,$A13,Eventos!$L$2:$L$209) -> 0 | I13: =SUMIF(Eventos!$A$2:$A$209,$A13,Eventos!$M$2:$M$209) -> 12 | J13: =SUMIF(Eventos!$A$2:$A$209,$A13,Eventos!$N$2:$N$209) -> 0 | K13: =COUNTIFS(Eventos!$A$2:$A$209,$A13,Eventos!$Q$2:$Q$209,"<>") -> 0
... A35: EV34 | B35: Guita 2 | D35: El mega libro del titular | E35: =COUNTIFS(Eventos!$A$2:$A$209,$A35,Eventos!$H$2:$H$209,1) -> 3 | F35: =COUNTIF(Eventos!$A$2:$A$209,$A35) -> 4 | G35: =SUMIF(Eventos!$A$2:$A$209,$A35,Eventos!$K$2:$K$209) -> 44 | H35: =SUMIF(Eventos!$A$2:$A$209,$A35,Eventos!$L$2:$L$209) -> 0 | I35: =SUMIF(Eventos!$A$2:$A$209,$A35,Eventos!$M$2:$M$209) -> 0 | J35: =SUMIF(Eventos!$A$2:$A$209,$A35,Eventos!$N$2:$N$209) -> 0 | K35: =COUNTIFS(Eventos!$A$2:$A$209,$A35,Eventos!$Q$2:$Q$209,"<>") -> 0
A36: EV35 | B36: Guita 3 | C36: Mitad de carrera | D36: La campaña del candidato | E36: =COUNTIFS(Eventos!$A$2:$A$209,$A36,Eventos!$H$2:$H$209,1) -> 3 | F36: =COUNTIF(Eventos!$A$2:$A$209,$A36) -> 3 | G36: =SUMIF(Eventos!$A$2:$A$209,$A36,Eventos!$K$2:$K$209) -> 12 | H36: =SUMIF(Eventos!$A$2:$A$209,$A36,Eventos!$L$2:$L$209) -> 0 | I36: =SUMIF(Eventos!$A$2:$A$209,$A36,Eventos!$M$2:$M$209) -> 0 | J36: =SUMIF(Eventos!$A$2:$A$209,$A36,Eventos!$N$2:$N$209) -> 12 | K36: =COUNTIFS(Eventos!$A$2:$A$209,$A36,Eventos!$Q$2:$Q$209,"<>") -> 0
A37: EV36 | B37: Guita 4 | C37: Avanzado | D37: La beca y el despido | E37: =COUNTIFS(Eventos!$A$2:$A$209,$A37,Eventos!$H$2:$H$209,1) -> 3 | F37: =COUNTIF(Eventos!$A$2:$A$209,$A37) -> 3 | G37: =SUMIF(Eventos!$A$2:$A$209,$A37,Eventos!$K$2:$K$209) -> 0 | H37: =SUMIF(Eventos!$A$2:$A$209,$A37,Eventos!$L$2:$L$209) -> -12 | I37: =SUMIF(Eventos!$A$2:$A$209,$A37,Eventos!$M$2:$M$209) -> -12 | J37: =SUMIF(Eventos!$A$2:$A$209,$A37,Eventos!$N$2:$N$209) -> 0 | K37: =COUNTIFS(Eventos!$A$2:$A$209,$A37,Eventos!$Q$2:$Q$209,"<>") -> 0
A38: EV37 | B38: Guita 5 | D38: Prácticas educativas | E38: =COUNTIFS(Eventos!$A$2:$A$209,$A38,Eventos!$H$2:$H$209,1) -> 2 | F38: =COUNTIF(Eventos!$A$2:$A$209,$A38) -> 2 | G38: =SUMIF(Eventos!$A$2:$A$209,$A38,Eventos!$K$2:$K$209) -> 0 | H38: =SUMIF(Eventos!$A$2:$A$209,$A38,Eventos!$L$2:$L$209) -> 0 | I38: =SUMIF(Eventos!$A$2:$A$209,$A38,Eventos!$M$2:$M$209) -> 0 | J38: =SUMIF(Eventos!$A$2:$A$209,$A38,Eventos!$N$2:$N$209) -> 0 | K38: =COUNTIFS(Eventos!$A$2:$A$209,$A38,Eventos!$Q$2:$Q$209,"<>") -> 0
A39: EV38 | B39: Guita 6 | D39: 8 horas por $200.000 | E39: =COUNTIFS(Eventos!$A$2:$A$209,$A39,Eventos!$H$2:$H$209,1) -> 2 | F39: =COUNTIF(Eventos!$A$2:$A$209,$A39) -> 3 | G39: =SUMIF(Eventos!$A$2:$A$209,$A39,Eventos!$K$2:$K$209) -> 0 | H39: =SUMIF(Eventos!$A$2:$A$209,$A39,Eventos!$L$2:$L$209) -> 36 | I39: =SUMIF(Eventos!$A$2:$A$209,$A39,Eventos!$M$2:$M$209) -> 0 | J39: =SUMIF(Eventos!$A$2:$A$209,$A39,Eventos!$N$2:$N$209) -> 0 | K39: =COUNTIFS(Eventos!$A$2:$A$209,$A39,Eventos!$Q$2:$Q$209,"<>") -> 0
A40: EV39 | B40: Guita 7 | D40: No alcanza para nada | E40: =COUNTIFS(Eventos!$A$2:$A$209,$A40,Eventos!$H$2:$H$209,1) -> 3 | F40: =COUNTIF(Eventos!$A$2:$A$209,$A40) -> 3 | G40: =SUMIF(Eventos!$A$2:$A$209,$A40,Eventos!$K$2:$K$209) -> 22 | H40: =SUMIF(Eventos!$A$2:$A$209,$A40,Eventos!$L$2:$L$209) -> -22 | I40: =SUMIF(Eventos!$A$2:$A$209,$A40,Eventos!$M$2:$M$209) -> 12 | J40: =SUMIF(Eventos!$A$2:$A$209,$A40,Eventos!$N$2:$N$209) -> 0 | K40: =COUNTIFS(Eventos!$A$2:$A$209,$A40,Eventos!$Q$2:$Q$209,"<>") -> 1
A41: EV40 | B41: Guita 8 | D41: Becas de trabajo en el comedor | E41: =COUNTIFS(Eventos!$A$2:$A$209,$A41,Eventos!$H$2:$H$209,1) -> 3 | F41: =COUNTIF(Eventos!$A$2:$A$209,$A41) -> 3 | G41: =SUMIF(Eventos!$A$2:$A$209,$A41,Eventos!$K$2:$K$209) -> 44 | H41: =SUMIF(Eventos!$A$2:$A$209,$A41,Eventos!$L$2:$L$209) -> 0 | I41: =SUMIF(Eventos!$A$2:$A$209,$A41,Eventos!$M$2:$M$209) -> 0 | J41: =SUMIF(Eventos!$A$2:$A$209,$A41,Eventos!$N$2:$N$209) -> -22 | K41: =COUNTIFS(Eventos!$A$2:$A$209,$A41,Eventos!$Q$2:$Q$209,"<>") -> 0
A42: EV41 | B42: Guita 9 | D42: La plata de la nona | E42: =COUNTIFS(Eventos!$A$2:$A$209,$A42,Eventos!$H$2:$H$209,1) -> 2 | F42: =COUNTIF(Eventos!$A$2:$A$209,$A42) -> 2 | G42: =SUMIF(Eventos!$A$2:$A$209,$A42,Eventos!$K$2:$K$209) -> 0 | H42: =SUMIF(Eventos!$A$2:$A$209,$A42,Eventos!$L$2:$L$209) -> 10 | I42: =SUMIF(Eventos!$A$2:$A$209,$A42,Eventos!$M$2:$M$209) -> 22 | J42: =SUMIF(Eventos!$A$2:$A$209,$A42,Eventos!$N$2:$N$209) -> 0 | K42: =COUNTIFS(Eventos!$A$2:$A$209,$A42,Eventos!$Q$2:$Q$209,"<>") -> 0
A43: EV42 | B43: Guita 10 | D43: El que vende los parciales | E43: =COUNTIFS(Eventos!$A$2:$A$209,$A43,Eventos!$H$2:$H$209,1) -> 3 | F43: =COUNTIF(Eventos!$A$2:$A$209,$A43) -> 5 | G43: =SUMIF(Eventos!$A$2:$A$209,$A43,Eventos!$K$2:$K$209) -> -104 | H43: =SUMIF(Eventos!$A$2:$A$209,$A43,Eventos!$L$2:$L$209) -> -22 | I43: =SUMIF(Eventos!$A$2:$A$209,$A43,Eventos!$M$2:$M$209) -> -24 | J43: =SUMIF(Eventos!$A$2:$A$209,$A43,Eventos!$N$2:$N$209) -> -24 | K43: =COUNTIFS(Eventos!$A$2:$A$209,$A43,Eventos!$Q$2:$Q$209,"<>") -> 0
A44: EV43 | B44: Conocimiento 1 | C44: Mitad de carrera | D44: La bicicleta al costado de las vías | E44: =COUNTIFS(Eventos!$A$2:$A$209,$A44,Eventos!$H$2:$H$209,1) -> 2 | F44: =COUNTIF(Eventos!$A$2:$A$209,$A44) -> 3 | G44: =SUMIF(Eventos!$A$2:$A$209,$A44,Eventos!$K$2:$K$209) -> -12 | H44: =SUMIF(Eventos!$A$2:$A$209,$A44,Eventos!$L$2:$L$209) -> 22 | I44: =SUMIF(Eventos!$A$2:$A$209,$A44,Eventos!$M$2:$M$209) -> 10 | J44: =SUMIF(Eventos!$A$2:$A$209,$A44,Eventos!$N$2:$N$209) -> 22 | K44: =COUNTIFS(Eventos!$A$2:$A$209,$A44,Eventos!$Q$2:$Q$209,"<>") -> 1
A45: EV44 | B45: Conocimiento 2 | D45: El porro antes del final | E45: =COUNTIFS(Eventos!$A$2:$A$209,$A45,Eventos!$H$2:$H$209,1) -> 2 | F45: =COUNTIF(Eventos!$A$2:$A$209,$A45) -> 4 | G45: =SUMIF(Eventos!$A$2:$A$209,$A45,Eventos!$K$2:$K$209) -> 0 | H45: =SUMIF(Eventos!$A$2:$A$209,$A45,Eventos!$L$2:$L$209) -> 32 | I45: =SUMIF(Eventos!$A$2:$A$209,$A45,Eventos!$M$2:$M$209) -> -12 | J45: =SUMIF(Eventos!$A$2:$A$209,$A45,Eventos!$N$2:$N$209) -> 0 | K45: =COUNTIFS(Eventos!$A$2:$A$209,$A45,Eventos!$Q$2:$Q$209,"<>") -> 0
A46: EV45 | B46: Conocimiento 3 | D46: El autor del que nadie habla | E46: =COUNTIFS(Eventos!$A$2:$A$209,$A46,Eventos!$H$2:$H$209,1) -> 3 | F46: =COUNTIF(Eventos!$A$2:$A$209,$A46) -> 5 | G46: =SUMIF(Eventos!$A$2:$A$209,$A46,Eventos!$K$2:$K$209) -> 0 | H46: =SUMIF(Eventos!$A$2:$A$209,$A46,Eventos!$L$2:$L$209) -> 24 | I46: =SUMIF(Eventos!$A$2:$A$209,$A46,Eventos!$M$2:$M$209) -> 12 | J46: =SUMIF(Eventos!$A$2:$A$209,$A46,Eventos!$N$2:$N$209) -> 24 | K46: =COUNTIFS(Eventos!$A$2:$A$209,$A46,Eventos!$Q$2:$Q$209,"<>") -> 0
A47: EV46 | B47: Conocimiento 4 | D47: La monografía que no pediste | E47: =COUNTIFS(Eventos!$A$2:$A$209,$A47,Eventos!$H$2:$H$209,1) -> 3 | F47: =COUNTIF(Eventos!$A$2:$A$209,$A47) -> 4 | G47: =SUMIF(Eventos!$A$2:$A$209,$A47,Eventos!$K$2:$K$209) -> 0 | H47: =SUMIF(Eventos!$A$2:$A$209,$A47,Eventos!$L$2:$L$209) -> -24 | I47: =SUMIF(Eventos!$A$2:$A$209,$A47,Eventos!$M$2:$M$209) -> 12 | J47: =SUMIF(Eventos!$A$2:$A$209,$A47,Eventos!$N$2:$N$209) -> -12 | K47: =COUNTIFS(Eventos!$A$2:$A$209,$A47,Eventos!$Q$2:$Q$209,"<>") -> 0
A48: EV47 | B48: Conocimiento 5 | D48: Cuatro horas de teórico y una lija tremenda | E48: =COUNTIFS(Eventos!$A$2:$A$209,$A48,Eventos!$H$2:$H$209,1) -> 3 | F48: =COUNTIF(Eventos!$A$2:$A$209,$A48) -> 4 | G48: =SUMIF(Eventos!$A$2:$A$209,$A48,Eventos!$K$2:$K$209) -> 22 | H48: =SUMIF(Eventos!$A$2:$A$209,$A48,Eventos!$L$2:$L$209) -> -12 | I48: =SUMIF(Eventos!$A$2:$A$209,$A48,Eventos!$M$2:$M$209) -> 12 | J48: =SUMIF(Eventos!$A$2:$A$209,$A48,Eventos!$N$2:$N$209) -> 24 | K48: =COUNTIFS(Eventos!$A$2:$A$209,$A48,Eventos!$Q$2:$Q$209,"<>") -> 1
A49: EV48 | B49: Conocimiento 6 | D49: El pelado de teoría política | E49: =COUNTIFS(Eventos!$A$2:$A$209,$A49,Eventos!$H$2:$H$209,1) -> 4 | F49: =COUNTIF(Eventos!$A$2:$A$209,$A49) -> 4 | G49: =SUMIF(Eventos!$A$2:$A$209,$A49,Eventos!$K$2:$K$209) -> -12 | H49: =SUMIF(Eventos!$A$2:$A$209,$A49,Eventos!$L$2:$L$209) -> 12 | I49: =SUMIF(Eventos!$A$2:$A$209,$A49,Eventos!$M$2:$M$209) -> 12 | J49: =SUMIF(Eventos!$A$2:$A$209,$A49,Eventos!$N$2:$N$209) -> 22 | K49: =COUNTIFS(Eventos!$A$2:$A$209,$A49,Eventos!$Q$2:$Q$209,"<>") -> 1
A50: EV49 | B50: Conocimiento 7 | D50: El trámite imposible | E50: =COUNTIFS(Eventos!$A$2:$A$209,$A50,Eventos!$H$2:$H$209,1) -> 3 | F50: =COUNTIF(Eventos!$A$2:$A$209,$A50) -> 3 | G50: =SUMIF(Eventos!$A$2:$A$209,$A50,Eventos!$K$2:$K$209) -> 0 | H50: =SUMIF(Eventos!$A$2:$A$209,$A50,Eventos!$L$2:$L$209) -> -50 | I50: =SUMIF(Eventos!$A$2:$A$209,$A50,Eventos!$M$2:$M$209) -> 12 | J50: =SUMIF(Eventos!$A$2:$A$209,$A50,Eventos!$N$2:$N$209) -> -25 | K50: =COUNTIFS(Eventos!$A$2:$A$209,$A50,Eventos!$Q$2:$Q$209,"<>") -> 0
A51: EV50 | B51: Fama 1 | D51: Vinieron a tapar los murales | E51: =COUNTIFS(Eventos!$A$2:$A$209,$A51,Eventos!$H$2:$H$209,1) -> 3 | F51: =COUNTIF(Eventos!$A$2:$A$209,$A51) -> 3 | G51: =SUMIF(Eventos!$A$2:$A$209,$A51,Eventos!$K$2:$K$209) -> 0 | H51: =SUMIF(Eventos!$A$2:$A$209,$A51,Eventos!$L$2:$L$209) -> -12 | I51: =SUMIF(Eventos!$A$2:$A$209,$A51,Eventos!$M$2:$M$209) -> 12 | J51: =SUMIF(Eventos!$A$2:$A$209,$A51,Eventos!$N$2:$N$209) -> 24 | K51: =COUNTIFS(Eventos!$A$2:$A$209,$A51,Eventos!$Q$2:$Q$209,"<>") -> 1
A52: EV51 | B52: Fama 2 | D52: Los noteros | E52: =COUNTIFS(Eventos!$A$2:$A$209,$A52,Eventos!$H$2:$H$209,1) -> 2 | F52: =COUNTIF(Eventos!$A$2:$A$209,$A52) -> 3 | G52: =SUMIF(Eventos!$A$2:$A$209,$A52,Eventos!$K$2:$K$209) -> 0 | H52: =SUMIF(Eventos!$A$2:$A$209,$A52,Eventos!$L$2:$L$209) -> 0 | I52: =SUMIF(Eventos!$A$2:$A$209,$A52,Eventos!$M$2:$M$209) -> 24 | J52: =SUMIF(Eventos!$A$2:$A$209,$A52,Eventos!$N$2:$N$209) -> 0 | K52: =COUNTIFS(Eventos!$A$2:$A$209,$A52,Eventos!$Q$2:$Q$209,"<>") -> 0
A53: EV52 | B53: Fama 3 | D53: El día de la expulsión | E53: =COUNTIFS(Eventos!$A$2:$A$209,$A53,Eventos!$H$2:$H$209,1) -> 3 | F53: =COUNTIF(Eventos!$A$2:$A$209,$A53) -> 3 | G53: =SUMIF(Eventos!$A$2:$A$209,$A53,Eventos!$K$2:$K$209) -> 0 | H53: =SUMIF(Eventos!$A$2:$A$209,$A53,Eventos!$L$2:$L$209) -> 0 | I53: =SUMIF(Eventos!$A$2:$A$209,$A53,Eventos!$M$2:$M$209) -> 22 | J53: =SUMIF(Eventos!$A$2:$A$209,$A53,Eventos!$N$2:$N$209) -> 0 | K53: =COUNTIFS(Eventos!$A$2:$A$209,$A53,Eventos!$Q$2:$Q$209,"<>") -> 1
A54: EV53 | B54: Fama 4 | D54: El pucho de la salida | E54: =COUNTIFS(Eventos!$A$2:$A$209,$A54,Eventos!$H$2:$H$209,1) -> 2 | F54: =COUNTIF(Eventos!$A$2:$A$209,$A54) -> 2 | G54: =SUMIF(Eventos!$A$2:$A$209,$A54,Eventos!$K$2:$K$209) -> 0 | H54: =SUMIF(Eventos!$A$2:$A$209,$A54,Eventos!$L$2:$L$209) -> 0 | I54: =SUMIF(Eventos!$A$2:$A$209,$A54,Eventos!$M$2:$M$209) -> 22 | J54: =SUMIF(Eventos!$A$2:$A$209,$A54,Eventos!$N$2:$N$209) -> 12 | K54: =COUNTIFS(Eventos!$A$2:$A$209,$A54,Eventos!$Q$2:$Q$209,"<>") -> 0
A55: EV54 | B55: Fama 5 | D55: Dejar una huella | E55: =COUNTIFS(Eventos!$A$2:$A$209,$A55,Eventos!$H$2:$H$209,1) -> 3 | F55: =COUNTIF(Eventos!$A$2:$A$209,$A55) -> 3 | G55: =SUMIF(Eventos!$A$2:$A$209,$A55,Eventos!$K$2:$K$209) -> 0 | H55: =SUMIF(Eventos!$A$2:$A$209,$A55,Eventos!$L$2:$L$209) -> 12 | I55: =SUMIF(Eventos!$A$2:$A$209,$A55,Eventos!$M$2:$M$209) -> -12 | J55: =SUMIF(Eventos!$A$2:$A$209,$A55,Eventos!$N$2:$N$209) -> 0 | K55: =COUNTIFS(Eventos!$A$2:$A$209,$A55,Eventos!$Q$2:$Q$209,"<>") -> 0
A56: EV55 | B56: Fama 6 | D56: ¿Te anotás para hablar? | E56: =COUNTIFS(Eventos!$A$2:$A$209,$A56,Eventos!$H$2:$H$209,1) -> 2 | F56: =COUNTIF(Eventos!$A$2:$A$209,$A56) -> 3 | G56: =SUMIF(Eventos!$A$2:$A$209,$A56,Eventos!$K$2:$K$209) -> 0 | H56: =SUMIF(Eventos!$A$2:$A$209,$A56,Eventos!$L$2:$L$209) -> -24 | I56: =SUMIF(Eventos!$A$2:$A$209,$A56,Eventos!$M$2:$M$209) -> 22 | J56: =SUMIF(Eventos!$A$2:$A$209,$A56,Eventos!$N$2:$N$209) -> -12 | K56: =COUNTIFS(Eventos!$A$2:$A$209,$A56,Eventos!$Q$2:$Q$209,"<>") -> 0
... A63: EV62 | B63: Política 6 | D63: Hacer pasadas | E63: =COUNTIFS(Eventos!$A$2:$A$209,$A63,Eventos!$H$2:$H$209,1) -> 3 | F63: =COUNTIF(Eventos!$A$2:$A$209,$A63) -> 3 | G63: =SUMIF(Eventos!$A$2:$A$209,$A63,Eventos!$K$2:$K$209) -> 0 | H63: =SUMIF(Eventos!$A$2:$A$209,$A63,Eventos!$L$2:$L$209) -> 0 | I63: =SUMIF(Eventos!$A$2:$A$209,$A63,Eventos!$M$2:$M$209) -> 12 | J63: =SUMIF(Eventos!$A$2:$A$209,$A63,Eventos!$N$2:$N$209) -> -12 | K63: =COUNTIFS(Eventos!$A$2:$A$209,$A63,Eventos!$Q$2:$Q$209,"<>") -> 0
A64: EV63 | B64: Historia 1 | C64: Ingresante | D64: La revolución social tiene que llegar | E64: =COUNTIFS(Eventos!$A$2:$A$209,$A64,Eventos!$H$2:$H$209,1) -> 2 | F64: =COUNTIF(Eventos!$A$2:$A$209,$A64) -> 2 | G64: =SUMIF(Eventos!$A$2:$A$209,$A64,Eventos!$K$2:$K$209) -> 12 | H64: =SUMIF(Eventos!$A$2:$A$209,$A64,Eventos!$L$2:$L$209) -> 0 | I64: =SUMIF(Eventos!$A$2:$A$209,$A64,Eventos!$M$2:$M$209) -> 12 | J64: =SUMIF(Eventos!$A$2:$A$209,$A64,Eventos!$N$2:$N$209) -> 12 | K64: =COUNTIFS(Eventos!$A$2:$A$209,$A64,Eventos!$Q$2:$Q$209,"<>") -> 0
A65: EV64 | B65: Historia 2 | C65: Ingresante | D65: Protesta en la puerta de OLGA | E65: =COUNTIFS(Eventos!$A$2:$A$209,$A65,Eventos!$H$2:$H$209,1) -> 2 | F65: =COUNTIF(Eventos!$A$2:$A$209,$A65) -> 3 | G65: =SUMIF(Eventos!$A$2:$A$209,$A65,Eventos!$K$2:$K$209) -> 0 | H65: =SUMIF(Eventos!$A$2:$A$209,$A65,Eventos!$L$2:$L$209) -> -22 | I65: =SUMIF(Eventos!$A$2:$A$209,$A65,Eventos!$M$2:$M$209) -> 12 | J65: =SUMIF(Eventos!$A$2:$A$209,$A65,Eventos!$N$2:$N$209) -> 12 | K65: =COUNTIFS(Eventos!$A$2:$A$209,$A65,Eventos!$Q$2:$Q$209,"<>") -> 0
A66: EV65 | B66: Historia 3 | C66: Ingresante | D66: La juntada intelectual | E66: =COUNTIFS(Eventos!$A$2:$A$209,$A66,Eventos!$H$2:$H$209,1) -> 2 | F66: =COUNTIF(Eventos!$A$2:$A$209,$A66) -> 4 | G66: =SUMIF(Eventos!$A$2:$A$209,$A66,Eventos!$K$2:$K$209) -> -22 | H66: =SUMIF(Eventos!$A$2:$A$209,$A66,Eventos!$L$2:$L$209) -> 0 | I66: =SUMIF(Eventos!$A$2:$A$209,$A66,Eventos!$M$2:$M$209) -> -12 | J66: =SUMIF(Eventos!$A$2:$A$209,$A66,Eventos!$N$2:$N$209) -> 12 | K66: =COUNTIFS(Eventos!$A$2:$A$209,$A66,Eventos!$Q$2:$Q$209,"<>") -> 0
A67: EV66 | B67: Historia 4 | C67: Intermedio | D67: La interna por el movimiento | E67: =COUNTIFS(Eventos!$A$2:$A$209,$A67,Eventos!$H$2:$H$209,1) -> 2 | F67: =COUNTIF(Eventos!$A$2:$A$209,$A67) -> 3 | G67: =SUMIF(Eventos!$A$2:$A$209,$A67,Eventos!$K$2:$K$209) -> 0 | H67: =SUMIF(Eventos!$A$2:$A$209,$A67,Eventos!$L$2:$L$209) -> 24 | I67: =SUMIF(Eventos!$A$2:$A$209,$A67,Eventos!$M$2:$M$209) -> 22 | J67: =SUMIF(Eventos!$A$2:$A$209,$A67,Eventos!$N$2:$N$209) -> 9 | K67: =COUNTIFS(Eventos!$A$2:$A$209,$A67,Eventos!$Q$2:$Q$209,"<>") -> 0
...
